pwesolowski@eden:~/containers$ srun -C dgx --cpus-per-task 1 --cpu-bind none --gpus 1 --mem 10G --time 1:0:0 --pty singularity run --nv -B /scratch/shared/pwesolowski rapidsai-dev_23.06-cuda11.8-devel-ubuntu22.04-py3.10.sif /bin/bash --rcfile singularity_rc
[WARN  tini (1633678)] Tini is not running as PID 1 .
Zombie processes will not be re-parented to Tini, so zombie reaping won't work.
To fix the problem, run Tini as PID 1.
This container image and its contents are governed by the NVIDIA Deep Learning Container License.
By pulling and using the container, you accept the terms and conditions of this license:
https://developer.download.nvidia.com/licenses/NVIDIA_Deep_Learning_Container_License.pdf

A JupyterLab server has been started!
To access it, visit http://localhost:8888 on your host machine.
Ensure the following arguments were added to "docker run" to expose the JupyterLab server to your host machine:
      -p 8888:8888 -p 8787:8787 -p 8786:8786
Make local folders visible by bind mounting to /rapids/notebooks/host
Singularity> python
Python 3.10.11 | packaged by conda-forge | (main, May 10 2023, 18:58:44) [GCC 11.3.0] on linux
Type "help", "copyright", "credits" or "license" for more information.
>>> from dask_cuda import LocalCUDACluster
>>> from dask.distributed import Client
>>> 
>>> cluster = LocalCUDACluster()
2023-07-01 23:54:20,834 - distributed.preloading - INFO - Creating preload: dask_cuda.initialize
2023-07-01 23:54:20,834 - distributed.preloading - INFO - Import preload module: dask_cuda.initialize
[Errno 22] Invalid argument
Traceback (most recent call last):
  File "/opt/conda/envs/rapids/lib/python3.10/site-packages/distributed/utils.py", line 752, in wrapper
    return await func(*args, **kwargs)
  File "/opt/conda/envs/rapids/lib/python3.10/site-packages/distributed/worker.py", line 1881, in plugin_add
    result = plugin.setup(worker=self)
  File "/opt/conda/envs/rapids/lib/python3.10/site-packages/dask_cuda-23.6.0-py3.10.egg/dask_cuda/utils.py", line 39, in setup
    os.sched_setaffinity(0, self.cores)
OSError: [Errno 22] Invalid argument
2023-07-01 23:54:21,872 - distributed.nanny - ERROR - Failed to start worker
Traceback (most recent call last):
  File "/opt/conda/envs/rapids/lib/python3.10/site-packages/distributed/core.py", line 536, in start
    await wait_for(self.start_unsafe(), timeout=timeout)
  File "/opt/conda/envs/rapids/lib/python3.10/site-packages/distributed/utils.py", line 1849, in wait_for
    return await asyncio.wait_for(fut, timeout)
  File "/opt/conda/envs/rapids/lib/python3.10/asyncio/tasks.py", line 408, in wait_for
    return await fut
  File "/opt/conda/envs/rapids/lib/python3.10/site-packages/distributed/worker.py", line 1478, in start_unsafe
    raise plugins_exceptions[0]
  File "/opt/conda/envs/rapids/lib/python3.10/site-packages/distributed/utils.py", line 752, in wrapper
    return await func(*args, **kwargs)
  File "/opt/conda/envs/rapids/lib/python3.10/site-packages/distributed/worker.py", line 1881, in plugin_add
    result = plugin.setup(worker=self)
  File "/opt/conda/envs/rapids/lib/python3.10/site-packages/dask_cuda-23.6.0-py3.10.egg/dask_cuda/utils.py", line 39, in setup
    os.sched_setaffinity(0, self.cores)
OSError: [Errno 22] Invalid argument

The above exception was the direct cause of the following exception:

Traceback (most recent call last):
  File "/opt/conda/envs/rapids/lib/python3.10/site-packages/distributed/nanny.py", line 930, in run
    async with worker:
  File "/opt/conda/envs/rapids/lib/python3.10/site-packages/distributed/core.py", line 549, in __aenter__
    await self
  File "/opt/conda/envs/rapids/lib/python3.10/site-packages/distributed/core.py", line 544, in start
    raise RuntimeError(f"{type(self).__name__} failed to start.") from exc
RuntimeError: Worker failed to start.
2023-07-01 23:54:21,901 - distributed.nanny - ERROR - Failed to start process
Traceback (most recent call last):
  File "/opt/conda/envs/rapids/lib/python3.10/site-packages/distributed/core.py", line 536, in start
    await wait_for(self.start_unsafe(), timeout=timeout)
  File "/opt/conda/envs/rapids/lib/python3.10/site-packages/distributed/utils.py", line 1849, in wait_for
    return await asyncio.wait_for(fut, timeout)
  File "/opt/conda/envs/rapids/lib/python3.10/asyncio/tasks.py", line 408, in wait_for
    return await fut
  File "/opt/conda/envs/rapids/lib/python3.10/site-packages/distributed/worker.py", line 1478, in start_unsafe
    raise plugins_exceptions[0]
  File "/opt/conda/envs/rapids/lib/python3.10/site-packages/distributed/utils.py", line 752, in wrapper
    return await func(*args, **kwargs)
  File "/opt/conda/envs/rapids/lib/python3.10/site-packages/distributed/worker.py", line 1881, in plugin_add
    result = plugin.setup(worker=self)
  File "/opt/conda/envs/rapids/lib/python3.10/site-packages/dask_cuda-23.6.0-py3.10.egg/dask_cuda/utils.py", line 39, in setup
OSError: [Errno 22] Invalid argument

The above exception was the direct cause of the following exception:

Traceback (most recent call last):
  File "/opt/conda/envs/rapids/lib/python3.10/site-packages/distributed/nanny.py", line 442, in instantiate
    result = await self.process.start()
  File "/opt/conda/envs/rapids/lib/python3.10/site-packages/distributed/nanny.py", line 718, in start
    msg = await self._wait_until_connected(uid)
  File "/opt/conda/envs/rapids/lib/python3.10/site-packages/distributed/nanny.py", line 866, in _wait_until_connected
    raise msg["exception"]
  File "/opt/conda/envs/rapids/lib/python3.10/site-packages/distributed/nanny.py", line 930, in run
    async with worker:
  File "/opt/conda/envs/rapids/lib/python3.10/site-packages/distributed/core.py", line 549, in __aenter__
    await self
  File "/opt/conda/envs/rapids/lib/python3.10/site-packages/distributed/core.py", line 544, in start
    raise RuntimeError(f"{type(self).__name__} failed to start.") from exc
RuntimeError: Worker failed to start.
Task exception was never retrieved
future: <Task finished name='Task-26' coro=<_wrap_awaitable() done, defined at /opt/conda/envs/rapids/lib/python3.10/site-packages/distributed/deploy/spec.py:118> exception=RuntimeError('Nanny failed to start.')>
Traceback (most recent call last):
  File "/opt/conda/envs/rapids/lib/python3.10/site-packages/distributed/core.py", line 536, in start
    await wait_for(self.start_unsafe(), timeout=timeout)
  File "/opt/conda/envs/rapids/lib/python3.10/site-packages/distributed/utils.py", line 1849, in wait_for
    return await asyncio.wait_for(fut, timeout)
  File "/opt/conda/envs/rapids/lib/python3.10/asyncio/tasks.py", line 408, in wait_for
    return await fut
  File "/opt/conda/envs/rapids/lib/python3.10/site-packages/distributed/worker.py", line 1478, in start_unsafe
    raise plugins_exceptions[0]
  File "/opt/conda/envs/rapids/lib/python3.10/site-packages/distributed/utils.py", line 752, in wrapper
    return await func(*args, **kwargs)
  File "/opt/conda/envs/rapids/lib/python3.10/site-packages/distributed/worker.py", line 1881, in plugin_add
    result = plugin.setup(worker=self)
  File "/opt/conda/envs/rapids/lib/python3.10/site-packages/dask_cuda-23.6.0-py3.10.egg/dask_cuda/utils.py", line 39, in setup
OSError: [Errno 22] Invalid argument

The above exception was the direct cause of the following exception:

Traceback (most recent call last):
  File "/opt/conda/envs/rapids/lib/python3.10/site-packages/distributed/core.py", line 536, in start
    await wait_for(self.start_unsafe(), timeout=timeout)
  File "/opt/conda/envs/rapids/lib/python3.10/site-packages/distributed/utils.py", line 1849, in wait_for
    return await asyncio.wait_for(fut, timeout)
  File "/opt/conda/envs/rapids/lib/python3.10/asyncio/tasks.py", line 408, in wait_for
    return await fut
  File "/opt/conda/envs/rapids/lib/python3.10/site-packages/distributed/nanny.py", line 368, in start_unsafe
    response = await self.instantiate()
  File "/opt/conda/envs/rapids/lib/python3.10/site-packages/distributed/nanny.py", line 442, in instantiate
    result = await self.process.start()
  File "/opt/conda/envs/rapids/lib/python3.10/site-packages/distributed/nanny.py", line 718, in start
    msg = await self._wait_until_connected(uid)
  File "/opt/conda/envs/rapids/lib/python3.10/site-packages/distributed/nanny.py", line 866, in _wait_until_connected
    raise msg["exception"]
  File "/opt/conda/envs/rapids/lib/python3.10/site-packages/distributed/nanny.py", line 930, in run
    async with worker:
  File "/opt/conda/envs/rapids/lib/python3.10/site-packages/distributed/core.py", line 549, in __aenter__
    await self
  File "/opt/conda/envs/rapids/lib/python3.10/site-packages/distributed/core.py", line 544, in start
    raise RuntimeError(f"{type(self).__name__} failed to start.") from exc
RuntimeError: Worker failed to start.

The above exception was the direct cause of the following exception:

Traceback (most recent call last):
  File "/opt/conda/envs/rapids/lib/python3.10/site-packages/distributed/deploy/spec.py", line 119, in _wrap_awaitable
    return await aw
  File "/opt/conda/envs/rapids/lib/python3.10/site-packages/distributed/core.py", line 544, in start
    raise RuntimeError(f"{type(self).__name__} failed to start.") from exc
RuntimeError: Nanny failed to start.
2023-07-01 23:54:22,180 - tornado.application - ERROR - Exception in callback functools.partial(<bound method IOLoop._discard_future_result of <tornado.platform.asyncio.AsyncIOLoop object at 0x7f8be7a8d120>>, <Task finished name='Task-25' coro=<SpecCluster._correct_state_internal() done, defined at /opt/conda/envs/rapids/lib/python3.10/site-packages/distributed/deploy/spec.py:341> exception=RuntimeError('Worker failed to start.')>)
Traceback (most recent call last):
  File "/opt/conda/envs/rapids/lib/python3.10/site-packages/distributed/core.py", line 536, in start
    await wait_for(self.start_unsafe(), timeout=timeout)
  File "/opt/conda/envs/rapids/lib/python3.10/site-packages/distributed/utils.py", line 1849, in wait_for
    return await asyncio.wait_for(fut, timeout)
  File "/opt/conda/envs/rapids/lib/python3.10/asyncio/tasks.py", line 408, in wait_for
    return await fut
  File "/opt/conda/envs/rapids/lib/python3.10/site-packages/distributed/worker.py", line 1478, in start_unsafe
    raise plugins_exceptions[0]
  File "/opt/conda/envs/rapids/lib/python3.10/site-packages/distributed/utils.py", line 752, in wrapper
    return await func(*args, **kwargs)
  File "/opt/conda/envs/rapids/lib/python3.10/site-packages/distributed/worker.py", line 1881, in plugin_add
    result = plugin.setup(worker=self)
  File "/opt/conda/envs/rapids/lib/python3.10/site-packages/dask_cuda-23.6.0-py3.10.egg/dask_cuda/utils.py", line 39, in setup
OSError: [Errno 22] Invalid argument

The above exception was the direct cause of the following exception:

Traceback (most recent call last):
  File "/opt/conda/envs/rapids/lib/python3.10/site-packages/tornado/ioloop.py", line 738, in _run_callback
    ret = callback()
  File "/opt/conda/envs/rapids/lib/python3.10/site-packages/tornado/ioloop.py", line 762, in _discard_future_result
    future.result()
  File "/opt/conda/envs/rapids/lib/python3.10/site-packages/distributed/deploy/spec.py", line 382, in _correct_state_internal
    await w  # for tornado gen.coroutine support
  File "/opt/conda/envs/rapids/lib/python3.10/site-packages/distributed/core.py", line 525, in start
    raise self.__startup_exc
  File "/opt/conda/envs/rapids/lib/python3.10/site-packages/distributed/core.py", line 536, in start
    await wait_for(self.start_unsafe(), timeout=timeout)
  File "/opt/conda/envs/rapids/lib/python3.10/site-packages/distributed/utils.py", line 1849, in wait_for
    return await asyncio.wait_for(fut, timeout)
  File "/opt/conda/envs/rapids/lib/python3.10/asyncio/tasks.py", line 408, in wait_for
    return await fut
  File "/opt/conda/envs/rapids/lib/python3.10/site-packages/distributed/nanny.py", line 368, in start_unsafe
    response = await self.instantiate()
  File "/opt/conda/envs/rapids/lib/python3.10/site-packages/distributed/nanny.py", line 442, in instantiate
    result = await self.process.start()
  File "/opt/conda/envs/rapids/lib/python3.10/site-packages/distributed/nanny.py", line 718, in start
    msg = await self._wait_until_connected(uid)
  File "/opt/conda/envs/rapids/lib/python3.10/site-packages/distributed/nanny.py", line 866, in _wait_until_connected
    raise msg["exception"]
  File "/opt/conda/envs/rapids/lib/python3.10/site-packages/distributed/nanny.py", line 930, in run
    async with worker:
  File "/opt/conda/envs/rapids/lib/python3.10/site-packages/distributed/core.py", line 549, in __aenter__
    await self
  File "/opt/conda/envs/rapids/lib/python3.10/site-packages/distributed/core.py", line 544, in start
    raise RuntimeError(f"{type(self).__name__} failed to start.") from exc
RuntimeError: Worker failed to start.
2023-07-01 23:54:23,369 - distributed.preloading - INFO - Creating preload: dask_cuda.initialize
2023-07-01 23:54:23,369 - distributed.preloading - INFO - Import preload module: dask_cuda.initialize
[Errno 22] Invalid argument
Traceback (most recent call last):
  File "/opt/conda/envs/rapids/lib/python3.10/site-packages/distributed/utils.py", line 752, in wrapper
    return await func(*args, **kwargs)
  File "/opt/conda/envs/rapids/lib/python3.10/site-packages/distributed/worker.py", line 1881, in plugin_add
    result = plugin.setup(worker=self)
  File "/opt/conda/envs/rapids/lib/python3.10/site-packages/dask_cuda-23.6.0-py3.10.egg/dask_cuda/utils.py", line 39, in setup
    os.sched_setaffinity(0, self.cores)
OSError: [Errno 22] Invalid argument
2023-07-01 23:54:24,275 - distributed.nanny - ERROR - Failed to start worker
Traceback (most recent call last):
  File "/opt/conda/envs/rapids/lib/python3.10/site-packages/distributed/core.py", line 536, in start
    await wait_for(self.start_unsafe(), timeout=timeout)
  File "/opt/conda/envs/rapids/lib/python3.10/site-packages/distributed/utils.py", line 1849, in wait_for
    return await asyncio.wait_for(fut, timeout)
  File "/opt/conda/envs/rapids/lib/python3.10/asyncio/tasks.py", line 408, in wait_for
    return await fut
  File "/opt/conda/envs/rapids/lib/python3.10/site-packages/distributed/worker.py", line 1478, in start_unsafe
    raise plugins_exceptions[0]
  File "/opt/conda/envs/rapids/lib/python3.10/site-packages/distributed/utils.py", line 752, in wrapper
    return await func(*args, **kwargs)
  File "/opt/conda/envs/rapids/lib/python3.10/site-packages/distributed/worker.py", line 1881, in plugin_add
    result = plugin.setup(worker=self)
  File "/opt/conda/envs/rapids/lib/python3.10/site-packages/dask_cuda-23.6.0-py3.10.egg/dask_cuda/utils.py", line 39, in setup
    os.sched_setaffinity(0, self.cores)
OSError: [Errno 22] Invalid argument

The above exception was the direct cause of the following exception:

Traceback (most recent call last):
  File "/opt/conda/envs/rapids/lib/python3.10/site-packages/distributed/nanny.py", line 930, in run
    async with worker:
  File "/opt/conda/envs/rapids/lib/python3.10/site-packages/distributed/core.py", line 549, in __aenter__
    await self
  File "/opt/conda/envs/rapids/lib/python3.10/site-packages/distributed/core.py", line 544, in start
    raise RuntimeError(f"{type(self).__name__} failed to start.") from exc
RuntimeError: Worker failed to start.
2023-07-01 23:54:24,291 - distributed.nanny - ERROR - Failed to start process
Traceback (most recent call last):
  File "/opt/conda/envs/rapids/lib/python3.10/site-packages/distributed/core.py", line 536, in start
    await wait_for(self.start_unsafe(), timeout=timeout)
  File "/opt/conda/envs/rapids/lib/python3.10/site-packages/distributed/utils.py", line 1849, in wait_for
    return await asyncio.wait_for(fut, timeout)
  File "/opt/conda/envs/rapids/lib/python3.10/asyncio/tasks.py", line 408, in wait_for
    return await fut
  File "/opt/conda/envs/rapids/lib/python3.10/site-packages/distributed/worker.py", line 1478, in start_unsafe
    raise plugins_exceptions[0]
  File "/opt/conda/envs/rapids/lib/python3.10/site-packages/distributed/utils.py", line 752, in wrapper
    return await func(*args, **kwargs)
  File "/opt/conda/envs/rapids/lib/python3.10/site-packages/distributed/worker.py", line 1881, in plugin_add
    result = plugin.setup(worker=self)
  File "/opt/conda/envs/rapids/lib/python3.10/site-packages/dask_cuda-23.6.0-py3.10.egg/dask_cuda/utils.py", line 39, in setup
OSError: [Errno 22] Invalid argument

The above exception was the direct cause of the following exception:

Traceback (most recent call last):
  File "/opt/conda/envs/rapids/lib/python3.10/site-packages/distributed/nanny.py", line 442, in instantiate
    result = await self.process.start()
  File "/opt/conda/envs/rapids/lib/python3.10/site-packages/distributed/nanny.py", line 718, in start
    msg = await self._wait_until_connected(uid)
  File "/opt/conda/envs/rapids/lib/python3.10/site-packages/distributed/nanny.py", line 866, in _wait_until_connected
    raise msg["exception"]
  File "/opt/conda/envs/rapids/lib/python3.10/site-packages/distributed/nanny.py", line 930, in run
    async with worker:
  File "/opt/conda/envs/rapids/lib/python3.10/site-packages/distributed/core.py", line 549, in __aenter__
    await self
  File "/opt/conda/envs/rapids/lib/python3.10/site-packages/distributed/core.py", line 544, in start
    raise RuntimeError(f"{type(self).__name__} failed to start.") from exc
RuntimeError: Worker failed to start.
Task exception was never retrieved
future: <Task finished name='Task-219' coro=<_wrap_awaitable() done, defined at /opt/conda/envs/rapids/lib/python3.10/site-packages/distributed/deploy/spec.py:118> exception=RuntimeError('Nanny failed to start.')>
Traceback (most recent call last):
  File "/opt/conda/envs/rapids/lib/python3.10/site-packages/distributed/core.py", line 536, in start
    await wait_for(self.start_unsafe(), timeout=timeout)
  File "/opt/conda/envs/rapids/lib/python3.10/site-packages/distributed/utils.py", line 1849, in wait_for
    return await asyncio.wait_for(fut, timeout)
  File "/opt/conda/envs/rapids/lib/python3.10/asyncio/tasks.py", line 408, in wait_for
    return await fut
  File "/opt/conda/envs/rapids/lib/python3.10/site-packages/distributed/worker.py", line 1478, in start_unsafe
    raise plugins_exceptions[0]
  File "/opt/conda/envs/rapids/lib/python3.10/site-packages/distributed/utils.py", line 752, in wrapper
    return await func(*args, **kwargs)
  File "/opt/conda/envs/rapids/lib/python3.10/site-packages/distributed/worker.py", line 1881, in plugin_add
    result = plugin.setup(worker=self)
  File "/opt/conda/envs/rapids/lib/python3.10/site-packages/dask_cuda-23.6.0-py3.10.egg/dask_cuda/utils.py", line 39, in setup
OSError: [Errno 22] Invalid argument

The above exception was the direct cause of the following exception:

Traceback (most recent call last):
  File "/opt/conda/envs/rapids/lib/python3.10/site-packages/distributed/core.py", line 536, in start
    await wait_for(self.start_unsafe(), timeout=timeout)
  File "/opt/conda/envs/rapids/lib/python3.10/site-packages/distributed/utils.py", line 1849, in wait_for
    return await asyncio.wait_for(fut, timeout)
  File "/opt/conda/envs/rapids/lib/python3.10/asyncio/tasks.py", line 408, in wait_for
    return await fut
  File "/opt/conda/envs/rapids/lib/python3.10/site-packages/distributed/nanny.py", line 368, in start_unsafe
    response = await self.instantiate()
  File "/opt/conda/envs/rapids/lib/python3.10/site-packages/distributed/nanny.py", line 442, in instantiate
    result = await self.process.start()
  File "/opt/conda/envs/rapids/lib/python3.10/site-packages/distributed/nanny.py", line 718, in start
    msg = await self._wait_until_connected(uid)
  File "/opt/conda/envs/rapids/lib/python3.10/site-packages/distributed/nanny.py", line 866, in _wait_until_connected
    raise msg["exception"]
  File "/opt/conda/envs/rapids/lib/python3.10/site-packages/distributed/nanny.py", line 930, in run
    async with worker:
  File "/opt/conda/envs/rapids/lib/python3.10/site-packages/distributed/core.py", line 549, in __aenter__
    await self
  File "/opt/conda/envs/rapids/lib/python3.10/site-packages/distributed/core.py", line 544, in start
    raise RuntimeError(f"{type(self).__name__} failed to start.") from exc
RuntimeError: Worker failed to start.

The above exception was the direct cause of the following exception:

Traceback (most recent call last):
  File "/opt/conda/envs/rapids/lib/python3.10/site-packages/distributed/deploy/spec.py", line 119, in _wrap_awaitable
    return await aw
  File "/opt/conda/envs/rapids/lib/python3.10/site-packages/distributed/core.py", line 544, in start
    raise RuntimeError(f"{type(self).__name__} failed to start.") from exc
RuntimeError: Nanny failed to start.
Traceback (most recent call last):
  File "/opt/conda/envs/rapids/lib/python3.10/site-packages/distributed/core.py", line 536, in start
    await wait_for(self.start_unsafe(), timeout=timeout)
  File "/opt/conda/envs/rapids/lib/python3.10/site-packages/distributed/utils.py", line 1849, in wait_for
    return await asyncio.wait_for(fut, timeout)
  File "/opt/conda/envs/rapids/lib/python3.10/asyncio/tasks.py", line 408, in wait_for
    return await fut
  File "/opt/conda/envs/rapids/lib/python3.10/site-packages/distributed/worker.py", line 1478, in start_unsafe
    raise plugins_exceptions[0]
  File "/opt/conda/envs/rapids/lib/python3.10/site-packages/distributed/utils.py", line 752, in wrapper
    return await func(*args, **kwargs)
  File "/opt/conda/envs/rapids/lib/python3.10/site-packages/distributed/worker.py", line 1881, in plugin_add
    result = plugin.setup(worker=self)
  File "/opt/conda/envs/rapids/lib/python3.10/site-packages/dask_cuda-23.6.0-py3.10.egg/dask_cuda/utils.py", line 39, in setup
OSError: [Errno 22] Invalid argument

The above exception was the direct cause of the following exception:

Traceback (most recent call last):
  File "<stdin>", line 1, in <module>
  File "/opt/conda/envs/rapids/lib/python3.10/site-packages/dask_cuda-23.6.0-py3.10.egg/dask_cuda/local_cuda_cluster.py", line 374, in __init__
    self.sync(self._correct_state)
  File "/opt/conda/envs/rapids/lib/python3.10/site-packages/distributed/utils.py", line 349, in sync
    return sync(
  File "/opt/conda/envs/rapids/lib/python3.10/site-packages/distributed/utils.py", line 416, in sync
    raise exc.with_traceback(tb)
  File "/opt/conda/envs/rapids/lib/python3.10/site-packages/distributed/utils.py", line 389, in f
    result = yield future
  File "/opt/conda/envs/rapids/lib/python3.10/site-packages/tornado/gen.py", line 767, in run
    value = future.result()
  File "/opt/conda/envs/rapids/lib/python3.10/site-packages/distributed/deploy/spec.py", line 382, in _correct_state_internal
    await w  # for tornado gen.coroutine support
  File "/opt/conda/envs/rapids/lib/python3.10/site-packages/distributed/core.py", line 525, in start
    raise self.__startup_exc
  File "/opt/conda/envs/rapids/lib/python3.10/site-packages/distributed/core.py", line 536, in start
    await wait_for(self.start_unsafe(), timeout=timeout)
  File "/opt/conda/envs/rapids/lib/python3.10/site-packages/distributed/utils.py", line 1849, in wait_for
    return await asyncio.wait_for(fut, timeout)
  File "/opt/conda/envs/rapids/lib/python3.10/asyncio/tasks.py", line 408, in wait_for
    return await fut
  File "/opt/conda/envs/rapids/lib/python3.10/site-packages/distributed/nanny.py", line 368, in start_unsafe
    response = await self.instantiate()
  File "/opt/conda/envs/rapids/lib/python3.10/site-packages/distributed/nanny.py", line 442, in instantiate
    result = await self.process.start()
  File "/opt/conda/envs/rapids/lib/python3.10/site-packages/distributed/nanny.py", line 718, in start
    msg = await self._wait_until_connected(uid)
  File "/opt/conda/envs/rapids/lib/python3.10/site-packages/distributed/nanny.py", line 866, in _wait_until_connected
    raise msg["exception"]
  File "/opt/conda/envs/rapids/lib/python3.10/site-packages/distributed/nanny.py", line 930, in run
    async with worker:
  File "/opt/conda/envs/rapids/lib/python3.10/site-packages/distributed/core.py", line 549, in __aenter__
    await self
  File "/opt/conda/envs/rapids/lib/python3.10/site-packages/distributed/core.py", line 544, in start
    raise RuntimeError(f"{type(self).__name__} failed to start.") from exc
RuntimeError: Worker failed to start.
>>> client = Client(cluster)
